Workbook

Sheet SUGESTAO_LOJA
A1: PREÇO DE VENDA - CHIQUINHO SORVETES | S1: MÉDIA % INSUMO | V1: MÉDIA % LUCRO REAL | Y1: MÉDIA % CUSTO REAL
S2: =AVERAGE(Q5:Q384) -> 0.28466386 | V2: =AVERAGE(J5:J384) -> 0.20312345 | Y2: =SUM(Tabela25[Total Custo])/SUM(Tabela25[Total Venda]) -> #DIV/0!
A4: CÓDIGO | B4: GRUPO | C4: NOME GRUPO | D4: DESCRIÇÃO DO ITEM | E4: VENDA MIN | F4: VENDA MAX | G4: SUGESTÃO | H4: DIFERENÇA | I4: PREÇO PRATICADO | J4: LUCRO REAL % | K4: LUCRO REAL R$ | L4: QUANT. VENDA | M4: % CUSTO REAL | N4: CUSTO | O4: Total Venda | P4: Total Custo | Q4: % INSUMOS
A5: 101400048 | B5: 1014 | C5: Acai | D5: Açai Monte o Seu 300ml | E5: 18 | F5: 20 | G5: =VLOOKUP(Tabela25[[#This Row],[CÓDIGO]],'[1]Estrutura Loja'!$B$3:$M$2941,5,0) -> 23.968455 | H5: =E5-G5 -> -5.9684548 | I5: 18 | J5: =(Tabela25[[#This Row],[PREÇO PRATICADO]]-((Tabela25[[#This Row],[PREÇO PRATICADO]])*([1]Informações!$H$6+[1]Informações!$H$15+[1]Informações!$H$19+[1]Informações!$H$20))-Tabela25[[#This Row],[CUSTO]])/Tabela25[[#This Row],[PREÇO PRATICADO]] -> 0.10782053 | K5: =Tabela25[[#This Row],[PREÇO PRATICADO]]*Tabela25[[#This Row],[LUCRO REAL %]] -> 1.9407696 | L5: 0 | M5: =IF(Tabela25[[#This Row],[QUANT. VENDA]]=0,0,((Tabela25[[#This Row],[CUSTO]]*Tabela25[[#This Row],[QUANT. VENDA]])/(Tabela25[[#This Row],[QUANT. VENDA]]*Tabela25[[#This Row],[PREÇO PRATICADO]]))) -> 0 | N5: =VLOOKUP(Tabela25[[#This Row],[CÓDIGO]],'[1]Estrutura Loja'!$B$3:$E$1825,4,0) -> 6.6632304 | O5: =Tabela25[[#This Row],[QUANT. VENDA]]*Tabela25[[#This Row],[PREÇO PRATICADO]] -> 0 | P5: =Tabela25[[#This Row],[QUANT. VENDA]]*Tabela25[[#This Row],[CUSTO]] -> 0 | Q5: =Tabela25[[#This Row],[CUSTO]]/Tabela25[[#This Row],[PREÇO PRATICADO]] -> 0.37017947
A6: 101400049 | B6: 1014 | C6: Acai | D6: Açai Monte o Seu 400ml | E6: 23 | F6: 25 | G6: =VLOOKUP(Tabela25[[#This Row],[CÓDIGO]],'[1]Estrutura Loja'!$B$3:$M$2941,5,0) -> 31.660926 | H6: =E6-G6 -> -8.6609262 | I6: 23 | J6: =(Tabela25[[#This Row],[PREÇO PRATICADO]]-((Tabela25[[#This Row],[PREÇO PRATICADO]])*([1]Informações!$H$6+[1]Informações!$H$15+[1]Informações!$H$19+[1]Informações!$H$20))-Tabela25[[#This Row],[CUSTO]])/Tabela25[[#This Row],[PREÇO PRATICADO]] -> 0.095315762 | K6: =Tabela25[[#This Row],[PREÇO PRATICADO]]*Tabela25[[#This Row],[LUCRO REAL %]] -> 2.1922625 | M6: =IF(Tabela25[[#This Row],[QUANT. VENDA]]=0,0,((Tabela25[[#This Row],[CUSTO]]*Tabela25[[#This Row],[QUANT. VENDA]])/(Tabela25[[#This Row],[QUANT. VENDA]]*Tabela25[[#This Row],[PREÇO PRATICADO]]))) -> 0 | N6: =VLOOKUP(Tabela25[[#This Row],[CÓDIGO]],'[1]Estrutura Loja'!$B$3:$E$1825,4,0) -> 8.8017375 | O6: =Tabela25[[#This Row],[QUANT. VENDA]]*Tabela25[[#This Row],[PREÇO PRATICADO]] -> 0 | P6: =Tabela25[[#This Row],[QUANT. VENDA]]*Tabela25[[#This Row],[CUSTO]] -> 0 | Q6: =Tabela25[[#This Row],[CUSTO]]/Tabela25[[#This Row],[PREÇO PRATICADO]] -> 0.38268424 | S6: *Média s/ Adicional, Açaí, Pote e Ed. Limitada
A7: 101400050 | B7: 1014 | C7: Acai | D7: Açai Monte o Seu 500ml | E7: 27 | F7: 29 | G7: =VLOOKUP(Tabela25[[#This Row],[CÓDIGO]],'[1]Estrutura Loja'!$B$3:$M$2941,5,0) -> 39.223772 | H7: =E7-G7 -> -12.223772 | I7: 27 | J7: =(Tabela25[[#This Row],[PREÇO PRATICADO]]-((Tabela25[[#This Row],[PREÇO PRATICADO]])*([1]Informações!$H$6+[1]Informações!$H$15+[1]Informações!$H$19+[1]Informações!$H$20))-Tabela25[[#This Row],[CUSTO]])/Tabela25[[#This Row],[PREÇO PRATICADO]] -> 0.074140425 | K7: =Tabela25[[#This Row],[PREÇO PRATICADO]]*Tabela25[[#This Row],[LUCRO REAL %]] -> 2.0017915 | M7: =IF(Tabela25[[#This Row],[QUANT. VENDA]]=0,0,((Tabela25[[#This Row],[CUSTO]]*Tabela25[[#This Row],[QUANT. VENDA]])/(Tabela25[[#This Row],[QUANT. VENDA]]*Tabela25[[#This Row],[PREÇO PRATICADO]]))) -> 0 | N7: =VLOOKUP(Tabela25[[#This Row],[CÓDIGO]],'[1]Estrutura Loja'!$B$3:$E$1825,4,0) -> 10.904209 | O7: =Tabela25[[#This Row],[QUANT. VENDA]]*Tabela25[[#This Row],[PREÇO PRATICADO]] -> 0 | P7: =Tabela25[[#This Row],[QUANT. VENDA]]*Tabela25[[#This Row],[CUSTO]] -> 0 | Q7: =Tabela25[[#This Row],[CUSTO]]/Tabela25[[#This Row],[PREÇO PRATICADO]] -> 0.40385958
A8: 140000001 | B8: 1014 | C8: Acai | D8: Ad Aç Amendoim triturado | E8: 2.5 | F8: 3 | G8: =VLOOKUP(Tabela25[[#This Row],[CÓDIGO]],'[1]Estrutura Loja'!$B$3:$M$2941,5,0) -> 2.553741 | H8: =E8-G8 -> -0.053741007 | I8: 2.5 | J8: =(Tabela25[[#This Row],[PREÇO PRATICADO]]-((Tabela25[[#This Row],[PREÇO PRATICADO]])*([1]Informações!$H$6+[1]Informações!$H$15+[1]Informações!$H$19+[1]Informações!$H$20))-Tabela25[[#This Row],[CUSTO]])/Tabela25[[#This Row],[PREÇO PRATICADO]] -> 0.194024 | K8: =Tabela25[[#This Row],[PREÇO PRATICADO]]*Tabela25[[#This Row],[LUCRO REAL %]] -> 0.48506 | M8: =IF(Tabela25[[#This Row],[QUANT. VENDA]]=0,0,((Tabela25[[#This Row],[CUSTO]]*Tabela25[[#This Row],[QUANT. VENDA]])/(Tabela25[[#This Row],[QUANT. VENDA]]*Tabela25[[#This Row],[PREÇO PRATICADO]]))) -> 0 | N8: =VLOOKUP(Tabela25[[#This Row],[CÓDIGO]],'[1]Estrutura Loja'!$B$3:$E$1825,4,0) -> 0.70994 | O8: =Tabela25[[#This Row],[QUANT. VENDA]]*Tabela25[[#This Row],[PREÇO PRATICADO]] -> 0 | P8: =Tabela25[[#This Row],[QUANT. VENDA]]*Tabela25[[#This Row],[CUSTO]] -> 0 | Q8: =Tabela25[[#This Row],[CUSTO]]/Tabela25[[#This Row],[PREÇO PRATICADO]] -> 0.283976 | S8: MÉDIA % INSUMO | V8: MÉDIA % LUCRO REAL
A9: 140000002 | B9: 1014 | C9: Acai | D9: Ad Aç Banana | E9: 2 | F9: 2.5 | G9: =VLOOKUP(Tabela25[[#This Row],[CÓDIGO]],'[1]Estrutura Loja'!$B$3:$M$2941,5,0) -> 1.8658273 | H9: =E9-G9 -> 0.13417266 | I9: 2 | J9: =(Tabela25[[#This Row],[PREÇO PRATICADO]]-((Tabela25[[#This Row],[PREÇO PRATICADO]])*([1]Informações!$H$6+[1]Informações!$H$15+[1]Informações!$H$19+[1]Informações!$H$20))-Tabela25[[#This Row],[CUSTO]])/Tabela25[[#This Row],[PREÇO PRATICADO]] -> 0.21865 | K9: =Tabela25[[#This Row],[PREÇO PRATICADO]]*Tabela25[[#This Row],[LUCRO REAL %]] -> 0.4373 | M9: =IF(Tabela25[[#This Row],[QUANT. VENDA]]=0,0,((Tabela25[[#This Row],[CUSTO]]*Tabela25[[#This Row],[QUANT. VENDA]])/(Tabela25[[#This Row],[QUANT. VENDA]]*Tabela25[[#This Row],[PREÇO PRATICADO]]))) -> 0 | N9: =VLOOKUP(Tabela25[[#This Row],[CÓDIGO]],'[1]Estrutura Loja'!$B$3:$E$1825,4,0) -> 0.5187 | O9: =Tabela25[[#This Row],[QUANT. VENDA]]*Tabela25[[#This Row],[PREÇO PRATICADO]] -> 0 | P9: =Tabela25[[#This Row],[QUANT. VENDA]]*Tabela25[[#This Row],[CUSTO]] -> 0 | Q9: =Tabela25[[#This Row],[CUSTO]]/Tabela25[[#This Row],[PREÇO PRATICADO]] -> 0.25935 | S9: 0.28 | V9: 0.21
A10: 140000003 | B10: 1014 | C10: Acai | D10: Ad Aç Morango | E10: 7.5 | F10: 8.5 | G10: =VLOOKUP(Tabela25[[#This Row],[CÓDIGO]],'[1]Estrutura Loja'!$B$3:$M$2941,5,0) -> 7.5539568 | H10: =E10-G10 -> -0.053956835 | I10: 7.5 | J10: =(Tabela25[[#This Row],[PREÇO PRATICADO]]-((Tabela25[[#This Row],[PREÇO PRATICADO]])*([1]Informações!$H$6+[1]Informações!$H$15+[1]Informações!$H$19+[1]Informações!$H$20))-Tabela25[[#This Row],[CUSTO]])/Tabela25[[#This Row],[PREÇO PRATICADO]] -> 0.198 | K10: =Tabela25[[#This Row],[PREÇO PRATICADO]]*Tabela25[[#This Row],[LUCRO REAL %]] -> 1.485 | M10: =IF(Tabela25[[#This Row],[QUANT. VENDA]]=0,0,((Tabela25[[#This Row],[CUSTO]]*Tabela25[[#This Row],[QUANT. VENDA]])/(Tabela25[[#This Row],[QUANT. VENDA]]*Tabela25[[#This Row],[PREÇO PRATICADO]]))) -> 0 | N10: =VLOOKUP(Tabela25[[#This Row],[CÓDIGO]],'[1]Estrutura Loja'!$B$3:$E$1825,4,0) -> 2.1 | O10: =Tabela25[[#This Row],[QUANT. VENDA]]*Tabela25[[#This Row],[PREÇO PRATICADO]] -> 0 | P10: =Tabela25[[#This Row],[QUANT. VENDA]]*Tabela25[[#This Row],[CUSTO]] -> 0 | Q10: =Tabela25[[#This Row],[CUSTO]]/Tabela25[[#This Row],[PREÇO PRATICADO]] -> 0.28
A11: 140000004 | B11: 1014 | C11: Acai | D11: Ad Aç Mini Disqueti | E11: 9.5 | F11: 10.5 | G11: =VLOOKUP(Tabela25[[#This Row],[CÓDIGO]],'[1]Estrutura Loja'!$B$3:$M$2941,5,0) -> 11.854676 | H11: =E11-G11 -> -2.3546763 | I11: 9.5 | J11: =(Tabela25[[#This Row],[PREÇO PRATICADO]]-((Tabela25[[#This Row],[PREÇO PRATICADO]])*([1]Informações!$H$6+[1]Informações!$H$15+[1]Informações!$H$19+[1]Informações!$H$20))-Tabela25[[#This Row],[CUSTO]])/Tabela25[[#This Row],[PREÇO PRATICADO]] -> 0.13109474 | K11: =Tabela25[[#This Row],[PREÇO PRATICADO]]*Tabela25[[#This Row],[LUCRO REAL %]] -> 1.2454 | M11: =IF(Tabela25[[#This Row],[QUANT. VENDA]]=0,0,((Tabela25[[#This Row],[CUSTO]]*Tabela25[[#This Row],[QUANT. VENDA]])/(Tabela25[[#This Row],[QUANT. VENDA]]*Tabela25[[#This Row],[PREÇO PRATICADO]]))) -> 0 | N11: =VLOOKUP(Tabela25[[#This Row],[CÓDIGO]],'[1]Estrutura Loja'!$B$3:$E$1825,4,0) -> 3.2956 | O11: =Tabela25[[#This Row],[QUANT. VENDA]]*Tabela25[[#This Row],[PREÇO PRATICADO]] -> 0 | P11: =Tabela25[[#This Row],[QUANT. VENDA]]*Tabela25[[#This Row],[CUSTO]] -> 0 | Q11: =Tabela25[[#This Row],[CUSTO]]/Tabela25[[#This Row],[PREÇO PRATICADO]] -> 0.34690526
A12: 140000005 | B12: 1014 | C12: Acai | D12: Ad Aç Leite Ninho | E12: 4.5 | F12: 4.5 | G12: =VLOOKUP(Tabela25[[#This Row],[CÓDIGO]],'[1]Estrutura Loja'!$B$3:$M$2941,5,0) -> 4.4527578 | H12: =E12-G12 -> 0.047242206 | I12: 4.5 | J12: =(Tabela25[[#This Row],[PREÇO PRATICADO]]-((Tabela25[[#This Row],[PREÇO PRATICADO]])*([1]Informações!$H$6+[1]Informações!$H$15+[1]Informações!$H$19+[1]Informações!$H$20))-Tabela25[[#This Row],[CUSTO]])/Tabela25[[#This Row],[PREÇO PRATICADO]] -> 0.20291852 | K12: =Tabela25[[#This Row],[PREÇO PRATICADO]]*Tabela25[[#This Row],[LUCRO REAL %]] -> 0.91313333 | M12: =IF(Tabela25[[#This Row],[QUANT. VENDA]]=0,0,((Tabela25[[#This Row],[CUSTO]]*Tabela25[[#This Row],[QUANT. VENDA]])/(Tabela25[[#This Row],[QUANT. VENDA]]*Tabela25[[#This Row],[PREÇO PRATICADO]]))) -> 0 | N12: =VLOOKUP(Tabela25[[#This Row],[CÓDIGO]],'[1]Estrutura Loja'!$B$3:$E$1825,4,0) -> 1.2378667 | O12: =Tabela25[[#This Row],[QUANT. VENDA]]*Tabela25[[#This Row],[PREÇO PRATICADO]] -> 0 | P12: =Tabela25[[#This Row],[QUANT. VENDA]]*Tabela25[[#This Row],[CUSTO]] -> 0 | Q12: =Tabela25[[#This Row],[CUSTO]]/Tabela25[[#This Row],[PREÇO PRATICADO]] -> 0.27508148
A13: 140000006 | B13: 1014 | C13: Acai | D13: Ad Aç Chocolate granulado | E13: 2.5 | F13: 3.5 | G13: =VLOOKUP(Tabela25[[#This Row],[CÓDIGO]],'[1]Estrutura Loja'!$B$3:$M$2941,5,0) -> 2.4446186 | H13: =E13-G13 -> 0.055381437 | I13: 2.5 | J13: =(Tabela25[[#This Row],[PREÇO PRATICADO]]-((Tabela25[[#This Row],[PREÇO PRATICADO]])*([1]Informações!$H$6+[1]Informações!$H$15+[1]Informações!$H$19+[1]Informações!$H$20))-Tabela25[[#This Row],[CUSTO]])/Tabela25[[#This Row],[PREÇO PRATICADO]] -> 0.20615842 | K13: =Tabela25[[#This Row],[PREÇO PRATICADO]]*Tabela25[[#This Row],[LUCRO REAL %]] -> 0.51539604 | M13: =IF(Tabela25[[#This Row],[QUANT. VENDA]]=0,0,((Tabela25[[#This Row],[CUSTO]]*Tabela25[[#This Row],[QUANT. VENDA]])/(Tabela25[[#This Row],[QUANT. VENDA]]*Tabela25[[#This Row],[PREÇO PRATICADO]]))) -> 0 | N13: =VLOOKUP(Tabela25[[#This Row],[CÓDIGO]],'[1]Estrutura Loja'!$B$3:$E$1825,4,0) -> 0.67960396 | O13: =Tabela25[[#This Row],[QUANT. VENDA]]*Tabela25[[#This Row],[PREÇO PRATICADO]] -> 0 | P13: =Tabela25[[#This Row],[QUANT. VENDA]]*Tabela25[[#This Row],[CUSTO]] -> 0 | Q13: =Tabela25[[#This Row],[CUSTO]]/Tabela25[[#This Row],[PREÇO PRATICADO]] -> 0.27184158
A14: 140000007 | B14: 1014 | C14: Acai | D14: Ad Aç Ovomaltine | E14: 3 | F14: 4 | G14: =VLOOKUP(Tabela25[[#This Row],[CÓDIGO]],'[1]Estrutura Loja'!$B$3:$M$2941,5,0) -> 3.3444221 | H14: =E14-G14 -> -0.34442206 | I14: 3 | J14: =(Tabela25[[#This Row],[PREÇO PRATICADO]]-((Tabela25[[#This Row],[PREÇO PRATICADO]])*([1]Informações!$H$6+[1]Informações!$H$15+[1]Informações!$H$19+[1]Informações!$H$20))-Tabela25[[#This Row],[CUSTO]])/Tabela25[[#This Row],[PREÇO PRATICADO]] -> 0.16808356 | K14: =Tabela25[[#This Row],[PREÇO PRATICADO]]*Tabela25[[#This Row],[LUCRO REAL %]] -> 0.50425067 | M14: =IF(Tabela25[[#This Row],[QUANT. VENDA]]=0,0,((Tabela25[[#This Row],[CUSTO]]*Tabela25[[#This Row],[QUANT. VENDA]])/(Tabela25[[#This Row],[QUANT. VENDA]]*Tabela25[[#This Row],[PREÇO PRATICADO]]))) -> 0 | N14: =VLOOKUP(Tabela25[[#This Row],[CÓDIGO]],'[1]Estrutura Loja'!$B$3:$E$1825,4,0) -> 0.92974933 | O14: =Tabela25[[#This Row],[QUANT. VENDA]]*Tabela25[[#This Row],[PREÇO PRATICADO]] -> 0 | P14: =Tabela25[[#This Row],[QUANT. VENDA]]*Tabela25[[#This Row],[CUSTO]] -> 0 | Q14: =Tabela25[[#This Row],[CUSTO]]/Tabela25[[#This Row],[PREÇO PRATICADO]] -> 0.30991644
A15: 140000008 | B15: 1014 | C15: =VLOOKUP(Tabela25[[#This Row],[GRUPO]],[1]Produto!H14:I363,2,0) -> Acai | D15: Ad Aç Leite Condensado Moça | E15: 5 | F15: 6 | G15: =VLOOKUP(Tabela25[[#This Row],[CÓDIGO]],'[1]Estrutura Loja'!$B$3:$M$2941,5,0) -> 5.0537292 | H15: =E15-G15 -> -0.053729169 | I15: 5 | J15: =(Tabela25[[#This Row],[PREÇO PRATICADO]]-((Tabela25[[#This Row],[PREÇO PRATICADO]])*([1]Informações!$H$6+[1]Informações!$H$15+[1]Informações!$H$19+[1]Informações!$H$20))-Tabela25[[#This Row],[CUSTO]])/Tabela25[[#This Row],[PREÇO PRATICADO]] -> 0.19701266 | K15: =Tabela25[[#This Row],[PREÇO PRATICADO]]*Tabela25[[#This Row],[LUCRO REAL %]] -> 0.98506329 | M15: =IF(Tabela25[[#This Row],[QUANT. VENDA]]=0,0,((Tabela25[[#This Row],[CUSTO]]*Tabela25[[#This Row],[QUANT. VENDA]])/(Tabela25[[#This Row],[QUANT. VENDA]]*Tabela25[[#This Row],[PREÇO PRATICADO]]))) -> 0 | N15: =VLOOKUP(Tabela25[[#This Row],[CÓDIGO]],'[1]Estrutura Loja'!$B$3:$E$1825,4,0) -> 1.4049367 | O15: =Tabela25[[#This Row],[QUANT. VENDA]]*Tabela25[[#This Row],[PREÇO PRATICADO]] -> 0 | P15: =Tabela25[[#This Row],[QUANT. VENDA]]*Tabela25[[#This Row],[CUSTO]] -> 0 | Q15: =Tabela25[[#This Row],[CUSTO]]/Tabela25[[#This Row],[PREÇO PRATICADO]] -> 0.28098734
A16: 140000009 | B16: 1014 | C16: Acai | D16: Ad Aç Ganache chiquinho | E16: 7.5 | F16: 8.5 | G16: =VLOOKUP(Tabela25[[#This Row],[CÓDIGO]],'[1]Estrutura Loja'!$B$3:$M$2941,5,0) -> 8.9503597 | H16: =E16-G16 -> -1.4503597 | I16: 7.5 | J16: =(Tabela25[[#This Row],[PREÇO PRATICADO]]-((Tabela25[[#This Row],[PREÇO PRATICADO]])*([1]Informações!$H$6+[1]Informações!$H$15+[1]Informações!$H$19+[1]Informações!$H$20))-Tabela25[[#This Row],[CUSTO]])/Tabela25[[#This Row],[PREÇO PRATICADO]] -> 0.14624 | K16: =Tabela25[[#This Row],[PREÇO PRATICADO]]*Tabela25[[#This Row],[LUCRO REAL %]] -> 1.0968 | M16: =IF(Tabela25[[#This Row],[QUANT. VENDA]]=0,0,((Tabela25[[#This Row],[CUSTO]]*Tabela25[[#This Row],[QUANT. VENDA]])/(Tabela25[[#This Row],[QUANT. VENDA]]*Tabela25[[#This Row],[PREÇO PRATICADO]]))) -> 0 | N16: =VLOOKUP(Tabela25[[#This Row],[CÓDIGO]],'[1]Estrutura Loja'!$B$3:$E$1825,4,0) -> 2.4882 | O16: =Tabela25[[#This Row],[QUANT. VENDA]]*Tabela25[[#This Row],[PREÇO PRATICADO]] -> 0 | P16: =Tabela25[[#This Row],[QUANT. VENDA]]*Tabela25[[#This Row],[CUSTO]] -> 0 | Q16: =Tabela25[[#This Row],[CUSTO]]/Tabela25[[#This Row],[PREÇO PRATICADO]] -> 0.33176
A17: 140000010 | B17: 1014 | C17: Acai | D17: Ad Aç Trufada Chiquinho | E17: 5 | F17: 6 | G17: =VLOOKUP(Tabela25[[#This Row],[CÓDIGO]],'[1]Estrutura Loja'!$B$3:$M$2941,5,0) -> 4.8098664 | H17: =E17-G17 -> 0.19013361 | I17: 5 | J17: =(Tabela25[[#This Row],[PREÇO PRATICADO]]-((Tabela25[[#This Row],[PREÇO PRATICADO]])*([1]Informações!$H$6+[1]Informações!$H$15+[1]Informações!$H$19+[1]Informações!$H$20))-Tabela25[[#This Row],[CUSTO]])/Tabela25[[#This Row],[PREÇO PRATICADO]] -> 0.21057143 | K17: =Tabela25[[#This Row],[PREÇO PRATICADO]]*Tabela25[[#This Row],[LUCRO REAL %]] -> 1.0528571 | M17: =IF(Tabela25[[#This Row],[QUANT. VENDA]]=0,0,((Tabela25[[#This Row],[CUSTO]]*Tabela25[[#This Row],[QUANT. VENDA]])/(Tabela25[[#This Row],[QUANT. VENDA]]*Tabela25[[#This Row],[PREÇO PRATICADO]]))) -> 0 | N17: =VLOOKUP(Tabela25[[#This Row],[CÓDIGO]],'[1]Estrutura Loja'!$B$3:$E$1825,4,0) -> 1.3371429 | O17: =Tabela25[[#This Row],[QUANT. VENDA]]*Tabela25[[#This Row],[PREÇO PRATICADO]] -> 0 | P17: =Tabela25[[#This Row],[QUANT. VENDA]]*Tabela25[[#This Row],[CUSTO]] -> 0 | Q17: =Tabela25[[#This Row],[CUSTO]]/Tabela25[[#This Row],[PREÇO PRATICADO]] -> 0.26742857
A18: 140000011 | B18: 1014 | C18: Acai | D18: Ad Aç Chantilly | E18: 2 | F18: 3 | G18: =VLOOKUP(Tabela25[[#This Row],[CÓDIGO]],'[1]Estrutura Loja'!$B$3:$M$2941,5,0) -> 2.2509521 | H18: =E18-G18 -> -0.25095213 | I18: 2 | J18: =(Tabela25[[#This Row],[PREÇO PRATICADO]]-((Tabela25[[#This Row],[PREÇO PRATICADO]])*([1]Informações!$H$6+[1]Informações!$H$15+[1]Informações!$H$19+[1]Informações!$H$20))-Tabela25[[#This Row],[CUSTO]])/Tabela25[[#This Row],[PREÇO PRATICADO]] -> 0.16511765 | K18: =Tabela25[[#This Row],[PREÇO PRATICADO]]*Tabela25[[#This Row],[LUCRO REAL %]] -> 0.33023531 | M18: =IF(Tabela25[[#This Row],[QUANT. VENDA]]=0,0,((Tabela25[[#This Row],[CUSTO]]*Tabela25[[#This Row],[QUANT. VENDA]])/(Tabela25[[#This Row],[QUANT. VENDA]]*Tabela25[[#This Row],[PREÇO PRATICADO]]))) -> 0 | N18: =VLOOKUP(Tabela25[[#This Row],[CÓDIGO]],'[1]Estrutura Loja'!$B$3:$E$1825,4,0) -> 0.62576469 | O18: =Tabela25[[#This Row],[QUANT. VENDA]]*Tabela25[[#This Row],[PREÇO PRATICADO]] -> 0 | P18: =Tabela25[[#This Row],[QUANT. VENDA]]*Tabela25[[#This Row],[CUSTO]] -> 0 | Q18: =Tabela25[[#This Row],[CUSTO]]/Tabela25[[#This Row],[PREÇO PRATICADO]] -> 0.31288235
A19: 140000012 | B19: 1014 | C19: Acai | D19: Ad Aç Doce de Leite | E19: 2.5 | F19: 3 | G19: =VLOOKUP(Tabela25[[#This Row],[CÓDIGO]],'[1]Estrutura Loja'!$B$3:$M$2941,5,0) -> 2.3535746 | H19: =E19-G19 -> 0.14642536 | I19: 2.5 | J19: =(Tabela25[[#This Row],[PREÇO PRATICADO]]-((Tabela25[[#This Row],[PREÇO PRATICADO]])*([1]Informações!$H$6+[1]Informações!$H$15+[1]Informações!$H$19+[1]Informações!$H$20))-Tabela25[[#This Row],[CUSTO]])/Tabela25[[#This Row],[PREÇO PRATICADO]] -> 0.2162825 | K19: =Tabela25[[#This Row],[PREÇO PRATICADO]]*Tabela25[[#This Row],[LUCRO REAL %]] -> 0.54070625 | M19: =IF(Tabela25[[#This Row],[QUANT. VENDA]]=0,0,((Tabela25[[#This Row],[CUSTO]]*Tabela25[[#This Row],[QUANT. VENDA]])/(Tabela25[[#This Row],[QUANT. VENDA]]*Tabela25[[#This Row],[PREÇO PRATICADO]]))) -> 0 | N19: =VLOOKUP(Tabela25[[#This Row],[CÓDIGO]],'[1]Estrutura Loja'!$B$3:$E$1825,4,0) -> 0.65429375 | O19: =Tabela25[[#This Row],[QUANT. VENDA]]*Tabela25[[#This Row],[PREÇO PRATICADO]] -> 0 | P19: =Tabela25[[#This Row],[QUANT. VENDA]]*Tabela25[[#This Row],[CUSTO]] -> 0 | Q19: =Tabela25[[#This Row],[CUSTO]]/Tabela25[[#This Row],[PREÇO PRATICADO]] -> 0.2617175
A20: 140000013 | B20: 1014 | C20: Acai | D20: Ad Aç Biscoito Negresco | E20: 5 | F20: 5 | G20: =VLOOKUP(Tabela25[[#This Row],[CÓDIGO]],'[1]Estrutura Loja'!$B$3:$M$2941,5,0) -> 4.0215827 | H20: =E20-G20 -> 0.97841727 | I20: 5 | J20: =(Tabela25[[#This Row],[PREÇO PRATICADO]]-((Tabela25[[#This Row],[PREÇO PRATICADO]])*([1]Informações!$H$6+[1]Informações!$H$15+[1]Informações!$H$19+[1]Informações!$H$20))-Tabela25[[#This Row],[CUSTO]])/Tabela25[[#This Row],[PREÇO PRATICADO]] -> 0.2544 | K20: =Tabela25[[#This Row],[PREÇO PRATICADO]]*Tabela25[[#This Row],[LUCRO REAL %]] -> 1.272 | M20: =IF(Tabela25[[#This Row],[QUANT. VENDA]]=0,0,((Tabela25[[#This Row],[CUSTO]]*Tabela25[[#This Row],[QUANT. VENDA]])/(Tabela25[[#This Row],[QUANT. VENDA]]*Tabela25[[#This Row],[PREÇO PRATICADO]]))) -> 0 | N20: =VLOOKUP(Tabela25[[#This Row],[CÓDIGO]],'[1]Estrutura Loja'!$B$3:$E$1825,4,0) -> 1.118 | O20: =Tabela25[[#This Row],[QUANT. VENDA]]*Tabela25[[#This Row],[PREÇO PRATICADO]] -> 0 | P20: =Tabela25[[#This Row],[QUANT. VENDA]]*Tabela25[[#This Row],[CUSTO]] -> 0 | Q20: =Tabela25[[#This Row],[CUSTO]]/Tabela25[[#This Row],[PREÇO PRATICADO]] -> 0.2236
A21: 140000014 | B21: 1014 | C21: Acai | D21: Ad Aç Marshmallow Torção fini | E21: 6 | F21: 6 | G21: =VLOOKUP(Tabela25[[#This Row],[CÓDIGO]],'[1]Estrutura Loja'!$B$3:$M$2941,5,0) -> 6.3777842 | H21: =E21-G21 -> -0.37778417 | I21: 6 | J21: =(Tabela25[[#This Row],[PREÇO PRATICADO]]-((Tabela25[[#This Row],[PREÇO PRATICADO]])*([1]Informações!$H$6+[1]Informações!$H$15+[1]Informações!$H$19+[1]Informações!$H$20))-Tabela25[[#This Row],[CUSTO]])/Tabela25[[#This Row],[PREÇO PRATICADO]] -> 0.182496 | K21: =Tabela25[[#This Row],[PREÇO PRATICADO]]*Tabela25[[#This Row],[LUCRO REAL %]] -> 1.094976 | M21: =IF(Tabela25[[#This Row],[QUANT. VENDA]]=0,0,((Tabela25[[#This Row],[CUSTO]]*Tabela25[[#This Row],[QUANT. VENDA]])/(Tabela25[[#This Row],[QUANT. VENDA]]*Tabela25[[#This Row],[PREÇO PRATICADO]]))) -> 0 | N21: =VLOOKUP(Tabela25[[#This Row],[CÓDIGO]],'[1]Estrutura Loja'!$B$3:$E$1825,4,0) -> 1.773024 | O21: =Tabela25[[#This Row],[QUANT. VENDA]]*Tabela25[[#This Row],[PREÇO PRATICADO]] -> 0 | P21: =Tabela25[[#This Row],[QUANT. VENDA]]*Tabela25[[#This Row],[CUSTO]] -> 0 | Q21: =Tabela25[[#This Row],[CUSTO]]/Tabela25[[#This Row],[PREÇO PRATICADO]] -> 0.295504
A22: 140000015 | B22: 1014 | C22: Acai | D22: Ad Aç Polpa Morango | E22: 5 | F22: 6 | G22: =VLOOKUP(Tabela25[[#This Row],[CÓDIGO]],'[1]Estrutura Loja'!$B$3:$M$2941,5,0) -> 5.5936612 | H22: =E22-G22 -> -0.59366117 | I22: 5 | J22: =(Tabela25[[#This Row],[PREÇO PRATICADO]]-((Tabela25[[#This Row],[PREÇO PRATICADO]])*([1]Informações!$H$6+[1]Informações!$H$15+[1]Informações!$H$19+[1]Informações!$H$20))-Tabela25[[#This Row],[CUSTO]])/Tabela25[[#This Row],[PREÇO PRATICADO]] -> 0.16699244 | K22: =Tabela25[[#This Row],[PREÇO PRATICADO]]*Tabela25[[#This Row],[LUCRO REAL %]] -> 0.8349622 | M22: =IF(Tabela25[[#This Row],[QUANT. VENDA]]=0,0,((Tabela25[[#This Row],[CUSTO]]*Tabela25[[#This Row],[QUANT. VENDA]])/(Tabela25[[#This Row],[QUANT. VENDA]]*Tabela25[[#This Row],[PREÇO PRATICADO]]))) -> 0 | N22: =VLOOKUP(Tabela25[[#This Row],[CÓDIGO]],'[1]Estrutura Loja'!$B$3:$E$1825,4,0) -> 1.5550378 | O22: =Tabela25[[#This Row],[QUANT. VENDA]]*Tabela25[[#This Row],[PREÇO PRATICADO]] -> 0 | P22: =Tabela25[[#This Row],[QUANT. VENDA]]*Tabela25[[#This Row],[CUSTO]] -> 0 | Q22: =Tabela25[[#This Row],[CUSTO]]/Tabela25[[#This Row],[PREÇO PRATICADO]] -> 0.31100756
A23: 140000016 | B23: 1014 | C23: Acai | D23: Ad Aç Polpa maracujá | E23: 6 | F23: 7 | G23: =VLOOKUP(Tabela25[[#This Row],[CÓDIGO]],'[1]Estrutura Loja'!$B$3:$M$2941,5,0) -> 6.1021758 | H23: =E23-G23 -> -0.10217582 | I23: 6 | J23: =(Tabela25[[#This Row],[PREÇO PRATICADO]]-((Tabela25[[#This Row],[PREÇO PRATICADO]])*([1]Informações!$H$6+[1]Informações!$H$15+[1]Informações!$H$19+[1]Informações!$H$20))-Tabela25[[#This Row],[CUSTO]])/Tabela25[[#This Row],[PREÇO PRATICADO]] -> 0.19526585 | K23: =Tabela25[[#This Row],[PREÇO PRATICADO]]*Tabela25[[#This Row],[LUCRO REAL %]] -> 1.1715951 | M23: =IF(Tabela25[[#This Row],[QUANT. VENDA]]=0,0,((Tabela25[[#This Row],[CUSTO]]*Tabela25[[#This Row],[QUANT. VENDA]])/(Tabela25[[#This Row],[QUANT. VENDA]]*Tabela25[[#This Row],[PREÇO PRATICADO]]))) -> 0 | N23: =VLOOKUP(Tabela25[[#This Row],[CÓDIGO]],'[1]Estrutura Loja'!$B$3:$E$1825,4,0) -> 1.6964049 | O23: =Tabela25[[#This Row],[QUANT. VENDA]]*Tabela25[[#This Row],[PREÇO PRATICADO]] -> 0 | P23: =Tabela25[[#This Row],[QUANT. VENDA]]*Tabela25[[#This Row],[CUSTO]] -> 0 | Q23: =Tabela25[[#This Row],[CUSTO]]/Tabela25[[#This Row],[PREÇO PRATICADO]] -> 0.28273415
A24: 140000017 | B24: 1014 | C24: Acai | D24: Ad Aç Polpa Frutas Vermelhas | E24: 6 | F24: 7 | G24: =VLOOKUP(Tabela25[[#This Row],[CÓDIGO]],'[1]Estrutura Loja'!$B$3:$M$2941,5,0) -> 7.0269345 | H24: =E24-G24 -> -1.0269345 | I24: 6 | J24: =(Tabela25[[#This Row],[PREÇO PRATICADO]]-((Tabela25[[#This Row],[PREÇO PRATICADO]])*([1]Informações!$H$6+[1]Informações!$H$15+[1]Informações!$H$19+[1]Informações!$H$20))-Tabela25[[#This Row],[CUSTO]])/Tabela25[[#This Row],[PREÇO PRATICADO]] -> 0.1524187 | K24: =Tabela25[[#This Row],[PREÇO PRATICADO]]*Tabela25[[#This Row],[LUCRO REAL %]] -> 0.9145122 | M24: =IF(Tabela25[[#This Row],[QUANT. VENDA]]=0,0,((Tabela25[[#This Row],[CUSTO]]*Tabela25[[#This Row],[QUANT. VENDA]])/(Tabela25[[#This Row],[QUANT. VENDA]]*Tabela25[[#This Row],[PREÇO PRATICADO]]))) -> 0 | N24: =VLOOKUP(Tabela25[[#This Row],[CÓDIGO]],'[1]Estrutura Loja'!$B$3:$E$1825,4,0) -> 1.9534878 | O24: =Tabela25[[#This Row],[QUANT. VENDA]]*Tabela25[[#This Row],[PREÇO PRATICADO]] -> 0 | P24: =Tabela25[[#This Row],[QUANT. VENDA]]*Tabela25[[#This Row],[CUSTO]] -> 0 | Q24: =Tabela25[[#This Row],[CUSTO]]/Tabela25[[#This Row],[PREÇO PRATICADO]] -> 0.3255813
A25: 140000018 | B25: 1014 | C25: Acai | D25: Ad Aç Creme Crocante Ovomaltine | E25: 7.5 | F25: 8.5 | G25: =VLOOKUP(Tabela25[[#This Row],[CÓDIGO]],'[1]Estrutura Loja'!$B$3:$M$2941,5,0) -> 7.5092806 | H25: =E25-G25 -> -0.0092805755 | I25: 7.5 | J25: =(Tabela25[[#This Row],[PREÇO PRATICADO]]-((Tabela25[[#This Row],[PREÇO PRATICADO]])*([1]Informações!$H$6+[1]Informações!$H$15+[1]Informações!$H$19+[1]Informações!$H$20))-Tabela25[[#This Row],[CUSTO]])/Tabela25[[#This Row],[PREÇO PRATICADO]] -> 0.199656 | K25: =Tabela25[[#This Row],[PREÇO PRATICADO]]*Tabela25[[#This Row],[LUCRO REAL %]] -> 1.49742 | M25: =IF(Tabela25[[#This Row],[QUANT. VENDA]]=0,0,((Tabela25[[#This Row],[CUSTO]]*Tabela25[[#This Row],[QUANT. VENDA]])/(Tabela25[[#This Row],[QUANT. VENDA]]*Tabela25[[#This Row],[PREÇO PRATICADO]]))) -> 0 | N25: =VLOOKUP(Tabela25[[#This Row],[CÓDIGO]],'[1]Estrutura Loja'!$B$3:$E$1825,4,0) -> 2.08758 | O25: =Tabela25[[#This Row],[QUANT. VENDA]]*Tabela25[[#This Row],[PREÇO PRATICADO]] -> 0 | P25: =Tabela25[[#This Row],[QUANT. VENDA]]*Tabela25[[#This Row],[CUSTO]] -> 0 | Q25: =Tabela25[[#This Row],[CUSTO]]/Tabela25[[#This Row],[PREÇO PRATICADO]] -> 0.278344
A26: 140000019 | B26: 1014 | C26: Acai | D26: Ad Aç Farofa Especial | E26: 4 | F26: 5 | G26: =VLOOKUP(Tabela25[[#This Row],[CÓDIGO]],'[1]Estrutura Loja'!$B$3:$M$2941,5,0) -> 3.4347817 | H26: =E26-G26 -> 0.56521832 | I26: 4 | J26: =(Tabela25[[#This Row],[PREÇO PRATICADO]]-((Tabela25[[#This Row],[PREÇO PRATICADO]])*([1]Informações!$H$6+[1]Informações!$H$15+[1]Informações!$H$19+[1]Informações!$H$20))-Tabela25[[#This Row],[CUSTO]])/Tabela25[[#This Row],[PREÇO PRATICADO]] -> 0.23928267 | K26: =Tabela25[[#This Row],[PREÇO PRATICADO]]*Tabela25[[#This Row],[LUCRO REAL %]] -> 0.95713069 | M26: =IF(Tabela25[[#This Row],[QUANT. VENDA]]=0,0,((Tabela25[[#This Row],[CUSTO]]*Tabela25[[#This Row],[QUANT. VENDA]])/(Tabela25[[#This Row],[QUANT. VENDA]]*Tabela25[[#This Row],[PREÇO PRATICADO]]))) -> 0 | N26: =VLOOKUP(Tabela25[[#This Row],[CÓDIGO]],'[1]Estrutura Loja'!$B$3:$E$1825,4,0) -> 0.95486931 | O26: =Tabela25[[#This Row],[QUANT. VENDA]]*Tabela25[[#This Row],[PREÇO PRATICADO]] -> 0 | P26: =Tabela25[[#This Row],[QUANT. VENDA]]*Tabela25[[#This Row],[CUSTO]] -> 0 | Q26: =Tabela25[[#This Row],[CUSTO]]/Tabela25[[#This Row],[PREÇO PRATICADO]] -> 0.23871733
A27: 140000020 | B27: 1014 | C27: Acai | D27: Ad Aç Granola | E27: 3 | F27: 3.5 | G27: =VLOOKUP(Tabela25[[#This Row],[CÓDIGO]],'[1]Estrutura Loja'!$B$3:$M$2941,5,0) -> 2.9810791 | H27: =E27-G27 -> 0.018920863 | I27: 3 | J27: =(Tabela25[[#This Row],[PREÇO PRATICADO]]-((Tabela25[[#This Row],[PREÇO PRATICADO]])*([1]Informações!$H$6+[1]Informações!$H$15+[1]Informações!$H$19+[1]Informações!$H$20))-Tabela25[[#This Row],[CUSTO]])/Tabela25[[#This Row],[PREÇO PRATICADO]] -> 0.20175333 | K27: =Tabela25[[#This Row],[PREÇO PRATICADO]]*Tabela25[[#This Row],[LUCRO REAL %]] -> 0.60526 | M27: =IF(Tabela25[[#This Row],[QUANT. VENDA]]=0,0,((Tabela25[[#This Row],[CUSTO]]*Tabela25[[#This Row],[QUANT. VENDA]])/(Tabela25[[#This Row],[QUANT. VENDA]]*Tabela25[[#This Row],[PREÇO PRATICADO]]))) -> 0 | N27: =VLOOKUP(Tabela25[[#This Row],[CÓDIGO]],'[1]Estrutura Loja'!$B$3:$E$1825,4,0) -> 0.82874 | O27: =Tabela25[[#This Row],[QUANT. VENDA]]*Tabela25[[#This Row],[PREÇO PRATICADO]] -> 0 | P27: =Tabela25[[#This Row],[QUANT. VENDA]]*Tabela25[[#This Row],[CUSTO]] -> 0 | Q27: =Tabela25[[#This Row],[CUSTO]]/Tabela25[[#This Row],[PREÇO PRATICADO]] -> 0.27624667
... A32: 140000025 | B32: 1014 | C32: Acai | D32: Ad Aç Ouro Branco | E32: 7.5 | F32: 7.5 | G32: =VLOOKUP(Tabela25[[#This Row],[CÓDIGO]],'[1]Estrutura Loja'!$B$3:$M$2941,5,0) -> 7.5876259 | H32: =E32-G32 -> -0.087625899 | I32: 7.5 | J32: =(Tabela25[[#This Row],[PREÇO PRATICADO]]-((Tabela25[[#This Row],[PREÇO PRATICADO]])*([1]Informações!$H$6+[1]Informações!$H$15+[1]Informações!$H$19+[1]Informações!$H$20))-Tabela25[[#This Row],[CUSTO]])/Tabela25[[#This Row],[PREÇO PRATICADO]] -> 0.196752 | K32: =Tabela25[[#This Row],[PREÇO PRATICADO]]*Tabela25[[#This Row],[LUCRO REAL %]] -> 1.47564 | M32: =IF(Tabela25[[#This Row],[QUANT. VENDA]]=0,0,((Tabela25[[#This Row],[CUSTO]]*Tabela25[[#This Row],[QUANT. VENDA]])/(Tabela25[[#This Row],[QUANT. VENDA]]*Tabela25[[#This Row],[PREÇO PRATICADO]]))) -> 0 | N32: =VLOOKUP(Tabela25[[#This Row],[CÓDIGO]],'[1]Estrutura Loja'!$B$3:$E$1825,4,0) -> 2.10936 | O32: =Tabela25[[#This Row],[QUANT. VENDA]]*Tabela25[[#This Row],[PREÇO PRATICADO]] -> 0 | P32: =Tabela25[[#This Row],[QUANT. VENDA]]*Tabela25[[#This Row],[CUSTO]] -> 0 | Q32: =Tabela25[[#This Row],[CUSTO]]/Tabela25[[#This Row],[PREÇO PRATICADO]] -> 0.281248
A33: 110000001 | B33: 1100 | C33: =VLOOKUP(Tabela25[[#This Row],[GRUPO]],[1]Produto!H180:I549,2,0) -> Adicional | D33: Ad Nutela | E33: 4.5 | F33: 5.5 | G33: =VLOOKUP(Tabela25[[#This Row],[CÓDIGO]],'[1]Estrutura Loja'!$B$3:$M$2941,5,0) -> 4.5627842 | H33: =E33-G33 -> -0.062784173 | I33: 4.5 | J33: =(Tabela25[[#This Row],[PREÇO PRATICADO]]-((Tabela25[[#This Row],[PREÇO PRATICADO]])*([1]Informações!$H$6+[1]Informações!$H$15+[1]Informações!$H$19+[1]Informações!$H$20))-Tabela25[[#This Row],[CUSTO]])/Tabela25[[#This Row],[PREÇO PRATICADO]] -> 0.19612133 | K33: =Tabela25[[#This Row],[PREÇO PRATICADO]]*Tabela25[[#This Row],[LUCRO REAL %]] -> 0.882546 | M33: =IF(Tabela25[[#This Row],[QUANT. VENDA]]=0,0,((Tabela25[[#This Row],[CUSTO]]*Tabela25[[#This Row],[QUANT. VENDA]])/(Tabela25[[#This Row],[QUANT. VENDA]]*Tabela25[[#This Row],[PREÇO PRATICADO]]))) -> 0 | N33: =VLOOKUP(Tabela25[[#This Row],[CÓDIGO]],'[1]Estrutura Loja'!$B$3:$E$1825,4,0) -> 1.268454 | O33: =Tabela25[[#This Row],[QUANT. VENDA]]*Tabela25[[#This Row],[PREÇO PRATICADO]] -> 0 | P33: =Tabela25[[#This Row],[QUANT. VENDA]]*Tabela25[[#This Row],[CUSTO]] -> 0 | Q33: =Tabela25[[#This Row],[CUSTO]]/Tabela25[[#This Row],[PREÇO PRATICADO]] -> 0.28187867
A34: 110000002 | B34: 1100 | C34: =VLOOKUP(Tabela25[[#This Row],[GRUPO]],[1]Produto!H181:I550,2,0) -> Adicional | D34: Ad Leite Ninho | E34: 3 | F34: 3 | G34: =VLOOKUP(Tabela25[[#This Row],[CÓDIGO]],'[1]Estrutura Loja'!$B$3:$M$2941,5,0) -> 2.2263789 | H34: =E34-G34 -> 0.7736211 | I34: 3 | J34: =(Tabela25[[#This Row],[PREÇO PRATICADO]]-((Tabela25[[#This Row],[PREÇO PRATICADO]])*([1]Informações!$H$6+[1]Informações!$H$15+[1]Informações!$H$19+[1]Informações!$H$20))-Tabela25[[#This Row],[CUSTO]])/Tabela25[[#This Row],[PREÇO PRATICADO]] -> 0.27168889 | K34: =Tabela25[[#This Row],[PREÇO PRATICADO]]*Tabela25[[#This Row],[LUCRO REAL %]] -> 0.81506667 | M34: =IF(Tabela25[[#This Row],[QUANT. VENDA]]=0,0,((Tabela25[[#This Row],[CUSTO]]*Tabela25[[#This Row],[QUANT. VENDA]])/(Tabela25[[#This Row],[QUANT. VENDA]]*Tabela25[[#This Row],[PREÇO PRATICADO]]))) -> 0 | N34: =VLOOKUP(Tabela25[[#This Row],[CÓDIGO]],'[1]Estrutura Loja'!$B$3:$E$1825,4,0) -> 0.61893333 | O34: =Tabela25[[#This Row],[QUANT. VENDA]]*Tabela25[[#This Row],[PREÇO PRATICADO]] -> 0 | P34: =Tabela25[[#This Row],[QUANT. VENDA]]*Tabela25[[#This Row],[CUSTO]] -> 0 | Q34: =Tabela25[[#This Row],[CUSTO]]/Tabela25[[#This Row],[PREÇO PRATICADO]] -> 0.20631111
A35: 110000003 | B35: 1100 | C35: =VLOOKUP(Tabela25[[#This Row],[GRUPO]],[1]Produto!H183:I552,2,0) -> Adicional | D35: Ad Chantilly | E35: 2 | F35: 2.5 | G35: =VLOOKUP(Tabela25[[#This Row],[CÓDIGO]],'[1]Estrutura Loja'!$B$3:$M$2941,5,0) -> 2.2509521 | H35: =E35-G35 -> -0.25095213 | I35: 2 | J35: =(Tabela25[[#This Row],[PREÇO PRATICADO]]-((Tabela25[[#This Row],[PREÇO PRATICADO]])*([1]Informações!$H$6+[1]Informações!$H$15+[1]Informações!$H$19+[1]Informações!$H$20))-Tabela25[[#This Row],[CUSTO]])/Tabela25[[#This Row],[PREÇO PRATICADO]] -> 0.16511765 | K35: =Tabela25[[#This Row],[PREÇO PRATICADO]]*Tabela25[[#This Row],[LUCRO REAL %]] -> 0.33023531 | M35: =IF(Tabela25[[#This Row],[QUANT. VENDA]]=0,0,((Tabela25[[#This Row],[CUSTO]]*Tabela25[[#This Row],[QUANT. VENDA]])/(Tabela25[[#This Row],[QUANT. VENDA]]*Tabela25[[#This Row],[PREÇO PRATICADO]]))) -> 0 | N35: =VLOOKUP(Tabela25[[#This Row],[CÓDIGO]],'[1]Estrutura Loja'!$B$3:$E$1825,4,0) -> 0.62576469 | O35: =Tabela25[[#This Row],[QUANT. VENDA]]*Tabela25[[#This Row],[PREÇO PRATICADO]] -> 0 | P35: =Tabela25[[#This Row],[QUANT. VENDA]]*Tabela25[[#This Row],[CUSTO]] -> 0 | Q35: =Tabela25[[#This Row],[CUSTO]]/Tabela25[[#This Row],[PREÇO PRATICADO]] -> 0.31288235
A36: 110000004 | B36: 1100 | C36: =VLOOKUP(Tabela25[[#This Row],[GRUPO]],[1]Produto!H184:I553,2,0) -> Adicional | D36: Ad Ganache Chiquinho | E36: 4 | F36: 5 | G36: =VLOOKUP(Tabela25[[#This Row],[CÓDIGO]],'[1]Estrutura Loja'!$B$3:$M$2941,5,0) -> 4.4751799 | H36: =E36-G36 -> -0.47517986 | I36: 4 | J36: =(Tabela25[[#This Row],[PREÇO PRATICADO]]-((Tabela25[[#This Row],[PREÇO PRATICADO]])*([1]Informações!$H$6+[1]Informações!$H$15+[1]Informações!$H$19+[1]Informações!$H$20))-Tabela25[[#This Row],[CUSTO]])/Tabela25[[#This Row],[PREÇO PRATICADO]] -> 0.166975 | K36: =Tabela25[[#This Row],[PREÇO PRATICADO]]*Tabela25[[#This Row],[LUCRO REAL %]] -> 0.6679 | M36: =IF(Tabela25[[#This Row],[QUANT. VENDA]]=0,0,((Tabela25[[#This Row],[CUSTO]]*Tabela25[[#This Row],[QUANT. VENDA]])/(Tabela25[[#This Row],[QUANT. VENDA]]*Tabela25[[#This Row],[PREÇO PRATICADO]]))) -> 0 | N36: =VLOOKUP(Tabela25[[#This Row],[CÓDIGO]],'[1]Estrutura Loja'!$B$3:$E$1825,4,0) -> 1.2441 | O36: =Tabela25[[#This Row],[QUANT. VENDA]]*Tabela25[[#This Row],[PREÇO PRATICADO]] -> 0 | P36: =Tabela25[[#This Row],[QUANT. VENDA]]*Tabela25[[#This Row],[CUSTO]] -> 0 | Q36: =Tabela25[[#This Row],[CUSTO]]/Tabela25[[#This Row],[PREÇO PRATICADO]] -> 0.311025
A37: 110000005 | B37: 1100 | C37: =VLOOKUP(Tabela25[[#This Row],[GRUPO]],[1]Produto!H185:I554,2,0) -> Adicional | D37: Ad Stracciatela Meio amarga | E37: 2 | F37: 2 | G37: =VLOOKUP(Tabela25[[#This Row],[CÓDIGO]],'[1]Estrutura Loja'!$B$3:$M$2941,5,0) -> 2.2191187 | H37: =E37-G37 -> -0.21911871 | I37: 2 | J37: =(Tabela25[[#This Row],[PREÇO PRATICADO]]-((Tabela25[[#This Row],[PREÇO PRATICADO]])*([1]Informações!$H$6+[1]Informações!$H$15+[1]Informações!$H$19+[1]Informações!$H$20))-Tabela25[[#This Row],[CUSTO]])/Tabela25[[#This Row],[PREÇO PRATICADO]] -> 0.1695425 | K37: =Tabela25[[#This Row],[PREÇO PRATICADO]]*Tabela25[[#This Row],[LUCRO REAL %]] -> 0.339085 | M37: =IF(Tabela25[[#This Row],[QUANT. VENDA]]=0,0,((Tabela25[[#This Row],[CUSTO]]*Tabela25[[#This Row],[QUANT. VENDA]])/(Tabela25[[#This Row],[QUANT. VENDA]]*Tabela25[[#This Row],[PREÇO PRATICADO]]))) -> 0 | N37: =VLOOKUP(Tabela25[[#This Row],[CÓDIGO]],'[1]Estrutura Loja'!$B$3:$E$1825,4,0) -> 0.616915 | O37: =Tabela25[[#This Row],[QUANT. VENDA]]*Tabela25[[#This Row],[PREÇO PRATICADO]] -> 0 | P37: =Tabela25[[#This Row],[QUANT. VENDA]]*Tabela25[[#This Row],[CUSTO]] -> 0 | Q37: =Tabela25[[#This Row],[CUSTO]]/Tabela25[[#This Row],[PREÇO PRATICADO]] -> 0.3084575
A38: 110000006 | B38: 1100 | C38: =VLOOKUP(Tabela25[[#This Row],[GRUPO]],[1]Produto!H186:I555,2,0) -> Adicional | D38: Ad Chocolate Granulado | E38: 1.5 | F38: 3 | G38: =VLOOKUP(Tabela25[[#This Row],[CÓDIGO]],'[1]Estrutura Loja'!$B$3:$M$2941,5,0) -> 1.5278866 | H38: =E38-G38 -> -0.027886602 | I38: 1.5 | J38: =(Tabela25[[#This Row],[PREÇO PRATICADO]]-((Tabela25[[#This Row],[PREÇO PRATICADO]])*([1]Informações!$H$6+[1]Informações!$H$15+[1]Informações!$H$19+[1]Informações!$H$20))-Tabela25[[#This Row],[CUSTO]])/Tabela25[[#This Row],[PREÇO PRATICADO]] -> 0.19483168 | K38: =Tabela25[[#This Row],[PREÇO PRATICADO]]*Tabela25[[#This Row],[LUCRO REAL %]] -> 0.29224752 | M38: =IF(Tabela25[[#This Row],[QUANT. VENDA]]=0,0,((Tabela25[[#This Row],[CUSTO]]*Tabela25[[#This Row],[QUANT. VENDA]])/(Tabela25[[#This Row],[QUANT. VENDA]]*Tabela25[[#This Row],[PREÇO PRATICADO]]))) -> 0 | N38: =VLOOKUP(Tabela25[[#This Row],[CÓDIGO]],'[1]Estrutura Loja'!$B$3:$E$1825,4,0) -> 0.42475248 | O38: =Tabela25[[#This Row],[QUANT. VENDA]]*Tabela25[[#This Row],[PREÇO PRATICADO]] -> 0 | P38: =Tabela25[[#This Row],[QUANT. VENDA]]*Tabela25[[#This Row],[CUSTO]] -> 0 | Q38: =Tabela25[[#This Row],[CUSTO]]/Tabela25[[#This Row],[PREÇO PRATICADO]] -> 0.28316832
A39: 110000007 | B39: 1100 | C39: =VLOOKUP(Tabela25[[#This Row],[GRUPO]],[1]Produto!H187:I556,2,0) -> Adicional | D39: Ad Cappuccino | E39: 2.5 | F39: 3 | G39: =VLOOKUP(Tabela25[[#This Row],[CÓDIGO]],'[1]Estrutura Loja'!$B$3:$M$2941,5,0) -> 3.1043345 | H39: =E39-G39 -> -0.60433453 | I39: 2.5 | J39: =(Tabela25[[#This Row],[PREÇO PRATICADO]]-((Tabela25[[#This Row],[PREÇO PRATICADO]])*([1]Informações!$H$6+[1]Informações!$H$15+[1]Informações!$H$19+[1]Informações!$H$20))-Tabela25[[#This Row],[CUSTO]])/Tabela25[[#This Row],[PREÇO PRATICADO]] -> 0.132798 | K39: =Tabela25[[#This Row],[PREÇO PRATICADO]]*Tabela25[[#This Row],[LUCRO REAL %]] -> 0.331995 | M39: =IF(Tabela25[[#This Row],[QUANT. VENDA]]=0,0,((Tabela25[[#This Row],[CUSTO]]*Tabela25[[#This Row],[QUANT. VENDA]])/(Tabela25[[#This Row],[QUANT. VENDA]]*Tabela25[[#This Row],[PREÇO PRATICADO]]))) -> 0 | N39: =VLOOKUP(Tabela25[[#This Row],[CÓDIGO]],'[1]Estrutura Loja'!$B$3:$E$1825,4,0) -> 0.863005 | O39: =Tabela25[[#This Row],[QUANT. VENDA]]*Tabela25[[#This Row],[PREÇO PRATICADO]] -> 0 | P39: =Tabela25[[#This Row],[QUANT. VENDA]]*Tabela25[[#This Row],[CUSTO]] -> 0 | Q39: =Tabela25[[#This Row],[CUSTO]]/Tabela25[[#This Row],[PREÇO PRATICADO]] -> 0.345202
A40: 110000008 | B40: 1100 | C40: =VLOOKUP(Tabela25[[#This Row],[GRUPO]],[1]Produto!H188:I557,2,0) -> Adicional | D40: Ad stracciatela Branca | E40: 2 | F40: 2 | G40: =VLOOKUP(Tabela25[[#This Row],[CÓDIGO]],'[1]Estrutura Loja'!$B$3:$M$2941,5,0) -> 2.6701439 | H40: =E40-G40 -> -0.67014388 | I40: 2 | J40: =(Tabela25[[#This Row],[PREÇO PRATICADO]]-((Tabela25[[#This Row],[PREÇO PRATICADO]])*([1]Informações!$H$6+[1]Informações!$H$15+[1]Informações!$H$19+[1]Informações!$H$20))-Tabela25[[#This Row],[CUSTO]])/Tabela25[[#This Row],[PREÇO PRATICADO]] -> 0.10685 | K40: =Tabela25[[#This Row],[PREÇO PRATICADO]]*Tabela25[[#This Row],[LUCRO REAL %]] -> 0.2137 | M40: =IF(Tabela25[[#This Row],[QUANT. VENDA]]=0,0,((Tabela25[[#This Row],[CUSTO]]*Tabela25[[#This Row],[QUANT. VENDA]])/(Tabela25[[#This Row],[QUANT. VENDA]]*Tabela25[[#This Row],[PREÇO PRATICADO]]))) -> 0 | N40: =VLOOKUP(Tabela25[[#This Row],[CÓDIGO]],'[1]Estrutura Loja'!$B$3:$E$1825,4,0) -> 0.7423 | O40: =Tabela25[[#This Row],[QUANT. VENDA]]*Tabela25[[#This Row],[PREÇO PRATICADO]] -> 0 | P40: =Tabela25[[#This Row],[QUANT. VENDA]]*Tabela25[[#This Row],[CUSTO]] -> 0 | Q40: =Tabela25[[#This Row],[CUSTO]]/Tabela25[[#This Row],[PREÇO PRATICADO]] -> 0.37115
A41: 110000009 | B41: 1100 | C41: =VLOOKUP(Tabela25[[#This Row],[GRUPO]],[1]Produto!H189:I558,2,0) -> Adicional | D41: Ad Creme de Menta | E41: 1.5 | F41: 2 | G41: =VLOOKUP(Tabela25[[#This Row],[CÓDIGO]],'[1]Estrutura Loja'!$B$3:$M$2941,5,0) -> 1.4589928 | H41: =E41-G41 -> 0.041007194 | I41: 1.5 | J41: =(Tabela25[[#This Row],[PREÇO PRATICADO]]-((Tabela25[[#This Row],[PREÇO PRATICADO]])*([1]Informações!$H$6+[1]Informações!$H$15+[1]Informações!$H$19+[1]Informações!$H$20))-Tabela25[[#This Row],[CUSTO]])/Tabela25[[#This Row],[PREÇO PRATICADO]] -> 0.2076 | K41: =Tabela25[[#This Row],[PREÇO PRATICADO]]*Tabela25[[#This Row],[LUCRO REAL %]] -> 0.3114 | M41: =IF(Tabela25[[#This Row],[QUANT. VENDA]]=0,0,((Tabela25[[#This Row],[CUSTO]]*Tabela25[[#This Row],[QUANT. VENDA]])/(Tabela25[[#This Row],[QUANT. VENDA]]*Tabela25[[#This Row],[PREÇO PRATICADO]]))) -> 0 | N41: =VLOOKUP(Tabela25[[#This Row],[CÓDIGO]],'[1]Estrutura Loja'!$B$3:$E$1825,4,0) -> 0.4056 | O41: =Tabela25[[#This Row],[QUANT. VENDA]]*Tabela25[[#This Row],[PREÇO PRATICADO]] -> 0 | P41: =Tabela25[[#This Row],[QUANT. VENDA]]*Tabela25[[#This Row],[CUSTO]] -> 0 | Q41: =Tabela25[[#This Row],[CUSTO]]/Tabela25[[#This Row],[PREÇO PRATICADO]] -> 0.2704
A42: 110000010 | B42: 1100 | C42: =VLOOKUP(Tabela25[[#This Row],[GRUPO]],[1]Produto!H190:I559,2,0) -> Adicional | D42: Ad Ovomaltine | E42: 1.5 | F42: 3 | G42: =VLOOKUP(Tabela25[[#This Row],[CÓDIGO]],'[1]Estrutura Loja'!$B$3:$M$2941,5,0) -> 1.672211 | H42: =E42-G42 -> -0.17221103 | I42: 1.5 | J42: =(Tabela25[[#This Row],[PREÇO PRATICADO]]-((Tabela25[[#This Row],[PREÇO PRATICADO]])*([1]Informações!$H$6+[1]Informações!$H$15+[1]Informações!$H$19+[1]Informações!$H$20))-Tabela25[[#This Row],[CUSTO]])/Tabela25[[#This Row],[PREÇO PRATICADO]] -> 0.16808356 | K42: =Tabela25[[#This Row],[PREÇO PRATICADO]]*Tabela25[[#This Row],[LUCRO REAL %]] -> 0.25212533 | M42: =IF(Tabela25[[#This Row],[QUANT. VENDA]]=0,0,((Tabela25[[#This Row],[CUSTO]]*Tabela25[[#This Row],[QUANT. VENDA]])/(Tabela25[[#This Row],[QUANT. VENDA]]*Tabela25[[#This Row],[PREÇO PRATICADO]]))) -> 0 | N42: =VLOOKUP(Tabela25[[#This Row],[CÓDIGO]],'[1]Estrutura Loja'!$B$3:$E$1825,4,0) -> 0.46487467 | O42: =Tabela25[[#This Row],[QUANT. VENDA]]*Tabela25[[#This Row],[PREÇO PRATICADO]] -> 0 | P42: =Tabela25[[#This Row],[QUANT. VENDA]]*Tabela25[[#This Row],[CUSTO]] -> 0 | Q42: =Tabela25[[#This Row],[CUSTO]]/Tabela25[[#This Row],[PREÇO PRATICADO]] -> 0.30991644
A43: 110000011 | B43: 1100 | C43: =VLOOKUP(Tabela25[[#This Row],[GRUPO]],[1]Produto!H191:I560,2,0) -> Adicional | D43: Ad Doce De Leite | E43: 2 | F43: 2 | G43: =VLOOKUP(Tabela25[[#This Row],[CÓDIGO]],'[1]Estrutura Loja'!$B$3:$M$2941,5,0) -> 1.1767873 | H43: =E43-G43 -> 0.82321268 | I43: 2 | J43: =(Tabela25[[#This Row],[PREÇO PRATICADO]]-((Tabela25[[#This Row],[PREÇO PRATICADO]])*([1]Informações!$H$6+[1]Informações!$H$15+[1]Informações!$H$19+[1]Informações!$H$20))-Tabela25[[#This Row],[CUSTO]])/Tabela25[[#This Row],[PREÇO PRATICADO]] -> 0.31442656 | K43: =Tabela25[[#This Row],[PREÇO PRATICADO]]*Tabela25[[#This Row],[LUCRO REAL %]] -> 0.62885313 | M43: =IF(Tabela25[[#This Row],[QUANT. VENDA]]=0,0,((Tabela25[[#This Row],[CUSTO]]*Tabela25[[#This Row],[QUANT. VENDA]])/(Tabela25[[#This Row],[QUANT. VENDA]]*Tabela25[[#This Row],[PREÇO PRATICADO]]))) -> 0 | N43: =VLOOKUP(Tabela25[[#This Row],[CÓDIGO]],'[1]Estrutura Loja'!$B$3:$E$1825,4,0) -> 0.32714688 | O43: =Tabela25[[#This Row],[QUANT. VENDA]]*Tabela25[[#This Row],[PREÇO PRATICADO]] -> 0 | P43: =Tabela25[[#This Row],[QUANT. VENDA]]*Tabela25[[#This Row],[CUSTO]] -> 0 | Q43: =Tabela25[[#This Row],[CUSTO]]/Tabela25[[#This Row],[PREÇO PRATICADO]] -> 0.16357344
A44: 110000012 | B44: 1100 | C44: =VLOOKUP(Tabela25[[#This Row],[GRUPO]],[1]Produto!H193:I561,2,0) -> Adicional | D44: Ad Calda Trufada | E44: 2.5 | F44: 3 | G44: =VLOOKUP(Tabela25[[#This Row],[CÓDIGO]],'[1]Estrutura Loja'!$B$3:$M$2941,5,0) -> 2.4049332 | H44: =E44-G44 -> 0.095066804 | I44: 2.5 | J44: =(Tabela25[[#This Row],[PREÇO PRATICADO]]-((Tabela25[[#This Row],[PREÇO PRATICADO]])*([1]Informações!$H$6+[1]Informações!$H$15+[1]Informações!$H$19+[1]Informações!$H$20))-Tabela25[[#This Row],[CUSTO]])/Tabela25[[#This Row],[PREÇO PRATICADO]] -> 0.21057143 | K44: =Tabela25[[#This Row],[PREÇO PRATICADO]]*Tabela25[[#This Row],[LUCRO REAL %]] -> 0.52642857 | M44: =IF(Tabela25[[#This Row],[QUANT. VENDA]]=0,0,((Tabela25[[#This Row],[CUSTO]]*Tabela25[[#This Row],[QUANT. VENDA]])/(Tabela25[[#This Row],[QUANT. VENDA]]*Tabela25[[#This Row],[PREÇO PRATICADO]]))) -> 0 | N44: =VLOOKUP(Tabela25[[#This Row],[CÓDIGO]],'[1]Estrutura Loja'!$B$3:$E$1825,4,0) -> 0.66857143 | O44: =Tabela25[[#This Row],[QUANT. VENDA]]*Tabela25[[#This Row],[PREÇO PRATICADO]] -> 0 | P44: =Tabela25[[#This Row],[QUANT. VENDA]]*Tabela25[[#This Row],[CUSTO]] -> 0 | Q44: =Tabela25[[#This Row],[CUSTO]]/Tabela25[[#This Row],[PREÇO PRATICADO]] -> 0.26742857
A45: 110000013 | B45: 1100 | C45: =VLOOKUP(Tabela25[[#This Row],[GRUPO]],[1]Produto!H196:I563,2,0) -> Adicional | D45: Ad Suco de limão | E45: 1.5 | F45: 3 | G45: =VLOOKUP(Tabela25[[#This Row],[CÓDIGO]],'[1]Estrutura Loja'!$B$3:$M$2941,5,0) -> 0.91726619 | H45: =E45-G45 -> 0.58273381 | I45: 1.5 | J45: =(Tabela25[[#This Row],[PREÇO PRATICADO]]-((Tabela25[[#This Row],[PREÇO PRATICADO]])*([1]Informações!$H$6+[1]Informações!$H$15+[1]Informações!$H$19+[1]Informações!$H$20))-Tabela25[[#This Row],[CUSTO]])/Tabela25[[#This Row],[PREÇO PRATICADO]] -> 0.308 | K45: =Tabela25[[#This Row],[PREÇO PRATICADO]]*Tabela25[[#This Row],[LUCRO REAL %]] -> 0.462 | M45: =IF(Tabela25[[#This Row],[QUANT. VENDA]]=0,0,((Tabela25[[#This Row],[CUSTO]]*Tabela25[[#This Row],[QUANT. VENDA]])/(Tabela25[[#This Row],[QUANT. VENDA]]*Tabela25[[#This Row],[PREÇO PRATICADO]]))) -> 0 | N45: =VLOOKUP(Tabela25[[#This Row],[CÓDIGO]],'[1]Estrutura Loja'!$B$3:$E$1825,4,0) -> 0.255 | O45: =Tabela25[[#This Row],[QUANT. VENDA]]*Tabela25[[#This Row],[PREÇO PRATICADO]] -> 0 | P45: =Tabela25[[#This Row],[QUANT. VENDA]]*Tabela25[[#This Row],[CUSTO]] -> 0 | Q45: =Tabela25[[#This Row],[CUSTO]]/Tabela25[[#This Row],[PREÇO PRATICADO]] -> 0.17
...
